Workbook

Sheet ESG Structure
B2: Full ESG Index | E2: Environment | I2: Social | M2: Composite
B3: Company | C3: Ticker | D3: Sector | E3: Climate Targets | F3: Investment & Transition | G3: Climate Reporting | H3: Environment Score | I3: DEI Targets & Representation | J3: DEI Programmes & Memberships | K3: Social Incentives | L3: Social Score | M3: Total Scores
B4: 3i | C4: III | D4: Financial services | E4: ='Environment '!G109 -> 0.6875 | F4: ='Environment '!L109 -> 0 | G4: ='Environment '!Q109 -> 0.2 | H4: ='Environment '!R109 -> 0.29583333 | I4: =Social!G110 -> 0.625 | J4: =Social!K110 -> 0.33333333 | K4: =Social!O110 -> 0.66666667 | L4: =Social!P110 -> 0.54166667 | M4: =(FullIndex[[#This Row],[Environment Score]]+FullIndex[[#This Row],[Social Score]])/2 -> 0.41875
B5: Admiral Group | C5: ADM | D5: Insurance | E5: ='Environment '!G110 -> 0.6875 | F5: ='Environment '!L110 -> 0.1875 | G5: ='Environment '!Q110 -> 0.3825 | H5: ='Environment '!R110 -> 0.41916667 | I5: =Social!G111 -> 0.525 | J5: =Social!K111 -> 0 | K5: =Social!O111 -> 0.83333333 | L5: =Social!P111 -> 0.45277778 | M5: =(FullIndex[[#This Row],[Environment Score]]+FullIndex[[#This Row],[Social Score]])/2 -> 0.43597222
B6: Airtel Africa | C6: AAF | D6: Telecommunications services | E6: ='Environment '!G111 -> 0.125 | F6: ='Environment '!L111 -> 0.0625 | G6: ='Environment '!Q111 -> 0.125 | H6: ='Environment '!R111 -> 0.10416667 | I6: =Social!G112 -> 0.3625 | J6: =Social!K112 -> 0 | K6: =Social!O112 -> 0.33333333 | L6: =Social!P112 -> 0.23194444 | M6: =(FullIndex[[#This Row],[Environment Score]]+FullIndex[[#This Row],[Social Score]])/2 -> 0.16805556
B7: Alliance Witan | C7: ALW | D7: Investment Trusts | E7: ='Environment '!G112 -> 0.25 | F7: ='Environment '!L112 -> 0 | G7: ='Environment '!Q112 -> 0.01 | H7: ='Environment '!R112 -> 0.086666667 | I7: =Social!G113 -> 0.25 | J7: =Social!K113 -> 0 | K7: =Social!O113 -> 0.5 | L7: =Social!P113 -> 0.25 | M7: =(FullIndex[[#This Row],[Environment Score]]+FullIndex[[#This Row],[Social Score]])/2 -> 0.16833333
B8: Anglo American | C8: AAL | D8: Mining | E8: ='Environment '!G113 -> 0.5125 | F8: ='Environment '!L113 -> 0.375 | G8: ='Environment '!Q113 -> 0.86 | H8: ='Environment '!R113 -> 0.5825 | I8: =Social!G114 -> 0.625 | J8: =Social!K114 -> 0.33333333 | K8: =Social!O114 -> 0.5 | L8: =Social!P114 -> 0.48611111 | M8: =(FullIndex[[#This Row],[Environment Score]]+FullIndex[[#This Row],[Social Score]])/2 -> 0.53430556
B9: Antofagasta | C9: ANTO | D9: Mining | E9: ='Environment '!G114 -> 0.65 | F9: ='Environment '!L114 -> 0.4375 | G9: ='Environment '!Q114 -> 0.5225 | H9: ='Environment '!R114 -> 0.53666667 | I9: =Social!G115 -> 0.4625 | J9: =Social!K115 -> 0 | K9: =Social!O115 -> 0.33333333 | L9: =Social!P115 -> 0.26527778 | M9: =(FullIndex[[#This Row],[Environment Score]]+FullIndex[[#This Row],[Social Score]])/2 -> 0.40097222
B10: Ashtead Group | C10: AHT | D10: Support services | E10: ='Environment '!G115 -> 0.4 | F10: ='Environment '!L115 -> 0 | G10: ='Environment '!Q115 -> 0.15 | H10: ='Environment '!R115 -> 0.18333333 | I10: =Social!G116 -> 0.425 | J10: =Social!K116 -> 0 | K10: =Social!O116 -> 0.5 | L10: =Social!P116 -> 0.30833333 | M10: =(FullIndex[[#This Row],[Environment Score]]+FullIndex[[#This Row],[Social Score]])/2 -> 0.24583333
B11: Associated British Foods | C11: ABF | D11: Food & tobacco | E11: ='Environment '!G116 -> 0.625 | F11: ='Environment '!L116 -> 0.5 | G11: ='Environment '!Q116 -> 0.5925 | H11: ='Environment '!R116 -> 0.5725 | I11: =Social!G117 -> 0.65 | J11: =Social!K117 -> 0.33333333 | K11: =Social!O117 -> 0.33333333 | L11: =Social!P117 -> 0.43888889 | M11: =(FullIndex[[#This Row],[Environment Score]]+FullIndex[[#This Row],[Social Score]])/2 -> 0.50569444
B12: AstraZeneca | C12: AZN | D12: Pharmaceuticals & biotechnology | E12: ='Environment '!G117 -> 1 | F12: ='Environment '!L117 -> 0.75 | G12: ='Environment '!Q117 -> 0.475 | H12: ='Environment '!R117 -> 0.74166667 | I12: =Social!G118 -> 0.5875 | J12: =Social!K118 -> 1 | K12: =Social!O118 -> 0.66666667 | L12: =Social!P118 -> 0.75138889 | M12: =(FullIndex[[#This Row],[Environment Score]]+FullIndex[[#This Row],[Social Score]])/2 -> 0.74652778
B13: Auto Trader Group | C13: AUTO | D13: Media | E13: ='Environment '!G118 -> 0.4375 | F13: ='Environment '!L118 -> 0 | G13: ='Environment '!Q118 -> 0.32 | H13: ='Environment '!R118 -> 0.2525 | I13: =Social!G119 -> 0.6875 | J13: =Social!K119 -> 0 | K13: =Social!O119 -> 1 | L13: =Social!P119 -> 0.5625 | M13: =(FullIndex[[#This Row],[Environment Score]]+FullIndex[[#This Row],[Social Score]])/2 -> 0.4075
B14: Aviva | C14: AV | D14: Life insurance | E14: ='Environment '!G119 -> 0.6875 | F14: ='Environment '!L119 -> 0.375 | G14: ='Environment '!Q119 -> 0.2275 | H14: ='Environment '!R119 -> 0.43 | I14: =Social!G120 -> 0.625 | J14: =Social!K120 -> 0 | K14: =Social!O120 -> 1 | L14: =Social!P120 -> 0.54166667 | M14: =(FullIndex[[#This Row],[Environment Score]]+FullIndex[[#This Row],[Social Score]])/2 -> 0.48583333
B15: Babcock International Group | C15: BAB | D15: Aerospace & defence | E15: ='Environment '!G120 -> 0.375 | F15: ='Environment '!L120 -> 0.1875 | G15: ='Environment '!Q120 -> 0.205 | H15: ='Environment '!R120 -> 0.25583333 | I15: =Social!G121 -> 0.625 | J15: =Social!K121 -> 0 | K15: =Social!O121 -> 0.5 | L15: =Social!P121 -> 0.375 | M15: =(FullIndex[[#This Row],[Environment Score]]+FullIndex[[#This Row],[Social Score]])/2 -> 0.31541667
... B103: WPP | C103: WPP | D103: Media | E103: ='Environment '!G208 -> 0.6875 | F103: ='Environment '!L208 -> 0.1875 | G103: ='Environment '!Q208 -> 0.3775 | H103: ='Environment '!R208 -> 0.4175 | I103: =Social!G209 -> 0.625 | J103: =Social!K209 -> 0.33333333 | K103: =Social!O209 -> 0.66666667 | L103: =Social!P209 -> 0.54166667 | M103: =(FullIndex[[#This Row],[Environment Score]]+FullIndex[[#This Row],[Social Score]])/2 -> 0.47958333

Sheet Environment 
B2: Social Raw Data (Weight: 40%) | U2: Environment
B3: Domains: | C3: E1 | H3: E2 | M3: E3 | U3: E1 - Climate Targets | V3: E2 - Investment and Transition Actions | W3: E3 - Climate Reporting
B4: Company | C4: Net Zero Commitment | D4: Scope Coverage | E4: SBTi Validation | F4: TPI Alignment | H4: Decarb/CapEx | I4: Green Bonds ($bn) | J4: Memberships | K4: Internal Carbon Price | M4: Sust. Report Page # | N4: CDP Score | O4: Climate KPI's | P4: Assurance Level
B5: 3i | C5: 2040 | D5: 1+2+3 | E5: Yes | F5: N/A | H5: None | I5: N/A | J5: No | K5: No | M5: 30 | N5: N/A | O5: N/A | P5: Limited | U5: 1. Net Zero Commitment Year | V5: 1. Decarbonisation Capex | W5: 1. Sustainability Report Page Number
B6: Admiral Group | C6: 2040 | D6: 1+2+3 | E6: Yes | F6: N/A | H6: None | I6: 0.75 | J6: No | K6: No | M6: 43 | N6: B | O6: N/A | P6: Limited | U6: Earlier = stronger commitment = higher inverted score. | V6: No action (None) = 0 | W6: Total Page Numbers
B7: Airtel Africa | C7: 2050 | D7: Unclear | E7: No | F7: N/A | H7: None | I7: 0.3 | J7: No | K7: No | M7: 50 | N7: N/A | O7: N/A | P7: None | U7: Example scoring: | V7: a) Plans to phase out carbon intensive Capex = 0.5 | W7: Score = (# disclosed ÷ 11)
B8: Alliance Witan | C8: 2050 | D8: 1+2 | E8: No | F8: N/A | H8: None | I8: N/A | J8: No | K8: No | M8: 4 | N8: N/A | O8: N/A | P8: None | U8: ≤ 2030 → 1.0 | V8: b) Has decarb. Investments/spend = 0.75
B9: Anglo American | C9: 2040 | D9: 1+2 | E9: No | F9: 4 | H9: None | I9: 0.74 | J9: No | K9: Yes | M9: 144 | N9: N/A | O9: Yes | P9: Reasonable | U9: 2031–2040 → 0.75 | V9: c) Has both a & b = 1 | W9: 2. CDP Score - https://knowesg.com/
B10: Antofagasta | C10: 2050 | D10: 1+2 | E10: Yes | F10: 3 | H10: B | I10: N/A | J10: No | K10: Yes | M10: 99 | N10: B | O10: No | P10: Limited | U10: 2041–2050 → 0.5 | W10: Map A/A- = 1 → B = 0.7 → C = 0.4 → D = 0.2 → F = 0
B11: Ashtead Group | C11: 2050 | D11: 1+2 | E11: No | F11: 3 | H11: None | I11: N/A | J11: No | K11: No | M11: N/A | N11: B | O11: No | P11: None | U11: > 2050 / no year → 0.2 | V11: 2. Green Bonds
B12: Associated British Foods | C12: 2050 | D12: 1+2+3 | E12: No | F12: 5 | H12: C | I12: N/A | J12: No | K12: Yes | M12: 27 | N12: B | O12: Yes | P12: Limited | U12: No commitment → 0 | V12: Issued > £1bn = 1 | W12: 3. Climate KPIs in Executive Pay
B13: AstraZeneca | C13: 2025 | D13: 1+2+3 | E13: Yes | F13: 5 | H13: C | I13: N/A | J13: Gold | K13: Yes | M13: 40 | N13: N/A | O13: Yes | P13: Limited | V13: £100m–1bn = 0.5 | W13: Binary:
B14: Auto Trader Group | C14: 2040 | D14: 1+2+3 | E14: No | F14: N/A | H14: None | I14: N/A | J14: No | K14: No | M14: 18 | N14: B | O14: N/A | P14: Limited | U14: 2. Scope Coverage | V14: <£100m = 0.25 | W14: Yes = 1
B15: Aviva | C15: 2040 | D15: 1+2+3 | E15: Yes | F15: N/A | H15: B | I15: N/A | J15: Yes | K15: No | M15: 11 | N15: A- | O15: N/A | P15: None | U15: Scopes 1+2+3 → 1 | V15: None = 0 | W15: No = 0
B16: Babcock International Group | C16: 2050 | D16: 1+2+3 | E16: No | F16: N/A | H16: B | I16: N/A | J16: No | K16: No | M16: 32 | N16: N/A | O16: N/A | P16: Limited | U16: Scopes 1+2 only → 0.5
B17: BAE Systems | C17: 2030 | D17: 1+2+3 | E17: Yes | F17: 4 | H17: None | I17: N/A | J17: No | K17: No | M17: 6 | N17: N/A | O17: Yes | P17: Limited | U17: Scope 1 only → 0.25 | V17: 3. RE100/EP100/EV100 Membership | W17: 4. Assurance Level
B18: Barclays | C18: 2050 | D18: 1+2+3 | E18: No | F18: 5 | H18: C | I18: 1.14 | J18: Gold | K18: Yes | M18: 41 | N18: A- | O18: Yes | P18: Limited | U18: None → 0 | V18: Binary: | W18: Reasonable = 1
B19: Barratt Developments | C19: 2040 | D19: Unclear | E19: Yes | F19: N/A | H19: None | I19: N/A | J19: No | K19: No | M19: N/A | N19: A | O19: N/A | P19: Limited | V19: Yes = 1, If Gold = 1.2 | W19: Limited = 0.5
B20: Beazley | C20: 2050 | D20: 1+2 | E20: No | F20: N/A | H20: None | I20: N/A | J20: No | K20: No | M20: 26 | N20: N/A | O20: N/A | P20: None | U20: 3. SBTi Validation | V20: No = 0 | W20: None = 0
B21: Berkeley Group Holdings | C21: 2450 | D21: 1+2+3 | E21: No | F21: N/A | H21: None | I21: 0.55 | J21: No | K21: No | M21: 30 | N21: N/A | O21: N/A | P21: Limited | U21: 1.5°C → 1
B22: BP | C22: 2050 | D22: 1+2+3 | E22: Yes | F22: 5 | H22: C | I22: N/A | J22: No | K22: Yes | M22: 49 | N22: N/A | O22: Yes | P22: None | U22: WB2°C → 0.75 | V22: 4. Internal Carbon Price Reported
B23: British American Tobacco | C23: 2050 | D23: 1+2+3 | E23: Yes | F23: 3 | H23: A | I23: N/A | J23: No | K23: Yes | M23: 104 | N23: A | O23: No | P23: None | U23: 2°C → 0.5 | V23: Binary:
B24: British Land | C24: 2030 | D24: 1+2 | E24: No | F24: N/A | H24: None | I24: N/A | J24: Yes | K24: No | M24: 27 | N24: N/A | O24: N/A | P24: None | U24: Commit only → 0.25 | V24: Yes = 1
B25: BT Group | C25: 2041 | D25: 1+2+3 | E25: Yes | F25: 5 | H25: C | I25: N/A | J25: Yes | K25: Yes | M25: 23 | N25: A | O25: Yes | P25: Reasonable | U25: No SBTi → 0 | V25: No = 0
B26: Bunzl | C26: 2050 | D26: 1+2+3 | E26: Yes | F26: 3 | H26: None | I26: N/A | J26: No | K26: No | M26: 26 | N26: N/A | O26: No | P26: Limited
B27: Burberry Group | C27: 2040 | D27: 1+2+3 | E27: Yes | F27: N/A | H27: None | I27: N/A | J27: Gold | K27: No | M27: 28 | N27: A- | O27: N/A | P27: None | U27: 4. TPI Alignment
B28: Centrica | C28: 2040 | D28: 1+2+3 | E28: Yes | F28: 5 | H28: C | I28: N/A | J28: No | K28: Yes | M28: 46 | N28: B | O28: Yes | P28: Limited | U28: TPI gives 0–4 or 0–5 level scores; normalize by dividing by max.
B29: Coca-Cola HBC | C29: 2040 | D29: 1+2+3 | E29: Yes | F29: 5 | H29: C | I29: N/A | J29: Yes | K29: Yes | M29: 14 | N29: A | O29: Yes | P29: Limited
B30: Compass Group | C30: 2050 | D30: 1+2+3 | E30: Yes | F30: 3 | H30: None | I30: 1.65 | J30: No | K30: No | M30: 42 | N30: N/A | O30: No | P30: Limited
B31: Convatec Group | C31: 2045 | D31: 1+2+3 | E31: No | F31: N/A | H31: None | I31: N/A | J31: No | K31: No | M31: N/A | N31: B | O31: N/A | P31: Limited
B32: Croda International | C32: 2050 | D32: 1+2+3 | E32: No | F32: 3 | H32: None | I32: N/A | J32: No | K32: Yes | M32: 25 | N32: A- | O32: No | P32: Limited
B33: DCC plc | C33: 2050 | D33: 1+2 | E33: Yes | F33: 3 | H33: None | I33: N/A | J33: No | K33: No | M33: 41 | N33: A | O33: No | P33: Limited
B34: Diageo | C34: 2050 | D34: 1+2+3 | E34: Yes | F34: 4 | H34: None | I34: N/A | J34: Yes | K34: No | M34: 71 | N34: N/A | O34: Yes | P34: Limited
B35: Diploma | C35: 2045 | D35: 1+2+3 | E35: No | F35: N/A | H35: None | I35: N/A | J35: No | K35: No | M35: 4 | N35: C | O35: N/A | P35: None
B36: Endeavour Mining | C36: 2050 | D36: 1+2 | E36: No | F36: 3 | H36: None | I36: N/A | J36: No | K36: Yes | M36: 98 | N36: B | O36: No | P36: Limited
B37: Entain | C37: 2035 | D37: 1+2+3 | E37: No | F37: N/A | H37: None | I37: N/A | J37: No | K37: No | M37: 42 | N37: B | O37: N/A | P37: Limited
B38: EasyJet | C38: 2050 | D38: 1+2+3 | E38: No | F38: 5 | H38: C | I38: N/A | J38: No | K38: Yes | M38: 5 | N38: N/A | O38: Yes | P38: Reasonable
B39: Experian | C39: 2050 | D39: Unclear | E39: Yes | F39: N/A | H39: None | I39: N/A | J39: No | K39: No | M39: 28 | N39: A- | O39: N/A | P39: Limited
B40: F&C Investment Trust | C40: 2050 | D40: Unclear | E40: No | F40: N/A | H40: None | I40: N/A | J40: No | K40: No | M40: N/A | N40: N/A | O40: N/A | P40: None
B41: Fresnillo | C41: 2030 | D41: Unclear | E41: No | F41: N/A | H41: None | I41: N/A | J41: No | K41: No | M41: 2 | N41: C | O41: N/A | P41: Limited
...

Sheet Social
B2: Social Raw Data (Weight: 40%) | R2: Social
B3: Domains: | C3: S1 | H3: S2 | L3: S3 | R3: S1 - DEI Targets & Representation | S3: S2 - Programmes & Memberships | T3: S3 - Social Governance & Incentives
B4: Company | C4: Gender Target | D4: Leadership Gender % | E4: Ethnicity Target | F4: Workforce Representation | H4: Stonewall/10000 | I4: Bloomberg | J4: Wdi Rep | L4: Diversity Linked to Exec Pay | M4: Board DEI Oversight | N4: Senior Management Target
B5: 3i | C5: Formal | D5: 0.4 | E5: Formal | H5: 1 | I5: No | J5: No | L5: Linked | M5: Yes | N5: No | R5: 1. Gender/Ethnicity Targets | S5: 1. DEI Memberships | T5: 1. Diversity Linked to Exec Pay
B6: Admiral Group | C6: Formal | D6: 0.455 | E6: Aspirational | H6: None | I6: No | J6: No | L6: Partially Linked | M6: Yes | N6: Yes | R6: Use your existing classification: | S6: Binary (0 or 1) for each: | T6: Linked = 1
B7: Airtel Africa | C7: Aspirational | D7: 0.333 | E7: Aspirational | H7: None | I7: No | J7: No | L7: Not Linked | M7: Yes | N7: No | S7: Stonewall | T7: Partially Linked = 0.5
B8: Alliance Witan | C8: N/A | D8: 0 | E8: Formal | H8: None | I8: No | J8: No | L8: Partially Linked | M8: Yes | N8: No | R8: Formal numeric target → 1 | S8: 10,000 Black Interns | T8: Not Linke = 0
B9: Anglo American | C9: Formal | D9: 0.455 | E9: Formal | H9: None | I9: Yes | J9: No | L9: Partially Linked | M9: Yes | N9: No | R9: Aspirational target → 0.6 | S9: Race at Work Charter
B10: Antofagasta | C10: Formal | D10: 0.308 | E10: Aspirational | H10: None | I10: No | J10: No | L10: Not Linked | M10: Yes | N10: No | R10: Metric only (“monitoring”) → 0.3 | S10: Any other DEI coalition | T10: 2. Board Oversight
B11: Ashtead Group | C11: Formal | D11: 0.222 | E11: Aspirational | H11: None | I11: No | J11: No | L11: Partially Linked | M11: Yes | N11: No | R11: No target → 0 | T11: Dedicated DEI/People Committee = 1
B12: Associated British Foods | C12: Formal | D12: 0.6 | E12: Aspirational | H12: None | I12: No | J12: Yes | L12: Not Linked | M12: Yes | N12: No | S12: Normalize by dividing by total possible memberships. | T12: Some oversight = 0.5
B13: AstraZeneca | C13: Formal | D13: 0.5 | E13: Aspirational | H13: 1 | I13: Yes | J13: Yes | L13: Linked | M13: Yes | N13: No | R13: 2. Representation thresholds | T13: None = 0
B14: Auto Trader Group | C14: Formal | D14: 0.556 | E14: Formal | H14: None | I14: No | J14: No | L14: Linked | M14: Yes | N14: Yes | R14: Gender at board/exec/workforce: | S14: 2. Internal DEI Programmes
B15: Aviva | C15: Formal | D15: 0.462 | E15: Formal | H15: None | I15: No | J15: No | L15: Linked | M15: Yes | N15: Yes | R15: ≥50% women → 1 | S15: Exec‑level DEI officer = 1 | T15: 3. Committed to Senior Management Target?
B16: Babcock International Group | C16: Formal | D16: 0.4 | E16: Formal | H16: None | I16: No | J16: No | L16: Partially Linked | M16: Yes | N16: No | R16: ≥40% → 0.75 | S16: ERGs, formal training programs = +0.25 each (cap at 1) | T16: Yes/No
B17: BAE Systems | C17: Formal | D17: 0.417 | E17: Aspirational | H17: None | I17: Yes | J17: No | L17: Linked | M17: Yes | N17: No | R17: ≥30% → 0.5
B18: Barclays | C18: Formal | D18: 0.462 | E18: Formal | H18: 1 | I18: No | J18: No | L18: Linked | M18: Yes | N18: Yes | R18: <30% → 0.25
B19: Barratt Developments | C19: Formal | D19: 0.5 | E19: Aspirational | H19: None | I19: No | J19: No | L19: Not Linked | M19: Yes | N19: Yes
B20: Beazley | C20: Formal | D20: 0.455 | E20: Formal | H20: None | I20: No | J20: No | L20: Linked | M20: Yes | N20: Yes | R20: Workforce Representation
B21: Berkeley Group Holdings | C21: Formal | D21: 0.444 | E21: Aspirational | H21: None | I21: No | J21: No | L21: Not Linked | M21: Yes | N21: Yes | R21: ≥15% exec = 1
B22: BP | C22: Formal | D22: 0.385 | E22: Aspirational | H22: None | I22: No | J22: No | L22: Linked | M22: Yes | N22: No | R22: ≥10% = 0.75
B23: British American Tobacco | C23: Formal | D23: 0.5 | E23: Formal | H23: None | I23: Yes | J23: Yes | L23: Linked | M23: Yes | N23: No | R23: ≥5% = 0.5
B24: British Land | C24: Formal | D24: 0.5 | E24: Formal | H24: 1 | I24: No | J24: No | L24: Partially Linked | M24: Yes | N24: Yes | R24: <5% = 0.25
B25: BT Group | C25: Aspirational | D25: 0.357 | E25: Formal | H25: None | I25: No | J25: No | L25: Partially Linked | M25: Yes | N25: Yes
B26: Bunzl | C26: Formal | D26: 0.556 | E26: Aspirational | H26: None | I26: No | J26: No | L26: Not Linked | M26: Yes | N26: No | R26: 3. Target Deadline Strength
B27: Burberry Group | C27: Formal | D27: 0.556 | E27: Formal | H27: 1 | I27: Yes | J27: Yes | L27: Linked | M27: Yes | N27: Yes | R27: 2025 or earlier → 1
B28: Centrica | C28: Formal | D28: 0.462 | E28: Formal | H28: None | I28: No | J28: Yes | L28: Partially Linked | M28: Yes | N28: Yes | R28: 2030 → 0.5
B29: Coca-Cola HBC | C29: Formal | D29: 0.278 | E29: Aspirational | H29: None | I29: Yes | J29: No | L29: Partially Linked | M29: Yes | N29: No | R29: No deadline → 0
B30: Compass Group | C30: Formal | D30: 0.417 | E30: Formal | H30: None | I30: No | J30: No | L30: Partially Linked | M30: Yes | N30: Yes
B31: Convatec Group | C31: Formal | D31: 0.556 | E31: Aspirational | H31: None | I31: No | J31: Yes | L31: Partially Linked | M31: Yes | N31: No
B32: Croda International | C32: Formal | D32: 0.333 | E32: Aspirational | H32: None | I32: No | J32: No | L32: Partially Linked | M32: Yes | N32: Yes
B33: DCC plc | C33: Formal | D33: 0.364 | E33: Aspirational | H33: None | I33: No | J33: No | L33: Not Linked | M33: Yes | N33: No
B34: Diageo | C34: Formal | D34: 0.778 | E34: Formal | H34: None | I34: Yes | J34: No | L34: Linked | M34: Yes | N34: No
B35: Diploma | C35: Aspirational | D35: 0.444 | E35: Aspirational | H35: None | I35: No | J35: No | L35: Not Linked | M35: Yes | N35: Yes
B36: Endeavour Mining | C36: Aspirational | D36: 0.4 | E36: Aspirational | H36: None | I36: No | J36: No | L36: Not Linked | M36: Yes | N36: Yes
B37: Entain | C37: Formal | D37: 0.364 | E37: Aspirational | H37: None | I37: No | J37: No | L37: Partially Linked | M37: Yes | N37: Yes
B38: EasyJet | C38: Formal | D38: 0.4 | E38: Formal | H38: None | I38: No | J38: No | L38: Partially Linked | M38: Yes | N38: No
B39: Experian | C39: Formal | D39: 0.444 | E39: Formal | H39: None | I39: No | J39: No | L39: Linked | M39: Yes | N39: No
B40: F&C Investment Trust | C40: Formal | D40: 0 | E40: Formal | H40: None | I40: No | J40: No | L40: Partially Linked | M40: Yes | N40: No
B41: Fresnillo | C41: Aspirational | D41: 0.385 | E41: Aspirational | H41: None | I41: No | J41: Yes | L41: Not Linked | M41: Yes | N41: No
...

Sheet Governance
B2: Governance Raw Data - Embedded in E and S and coppied here | N2: Governance Treatment
B3: Domains: | C3: G1 | H3: G2
B4: Company | C4: Sust. Report Page # | D4: CDP Score | E4: Climate KPI's | F4: Assurance Level | H4: Diversity Linked to Exec Pay | I4: Board DEI Oversight | J4: Senior Management Target | N4: Governance-related indicators are treated as embedded within the live Environment and Social frameworks rather than presented as a
B5: 3i | C5: 30 | D5: N/A | E5: N/A | F5: Limited | H5: Linked | I5: Yes | J5: No | N5: standalone score. In the underlying methodology, governance appears through strategy, oversight, incentives, transparency, and
B6: Admiral Group | C6: 43 | D6: B | E6: N/A | F6: Limited | H6: Partially Linked | I6: Yes | J6: Yes | N6: assurance-related signals. These include ESG integration into corporate strategy and risk management, board-level oversight structures,
B7: Airtel Africa | C7: 50 | D7: N/A | E7: N/A | F7: None | H7: Not Linked | I7: Yes | J7: No | N7: diversity-linked incentives, formal committees, external frameworks, and third-party assurance.
B8: Alliance Witan | C8: 4 | D8: N/A | E8: N/A | F8: None | H8: Partially Linked | I8: Yes | J8: No
B9: Anglo American | C9: 144 | D9: N/A | E9: Yes | F9: Reasonable | H9: Partially Linked | I9: Yes | J9: No | N9: For the website, those governance signals are reflected primarily through the reporting, oversight, and incentive-related measures already
B10: Antofagasta | C10: 99 | D10: B | E10: No | F10: Limited | H10: Not Linked | I10: Yes | J10: No | N10: captured inside the Environment and Social domains. This keeps governance visible in the logic of the index without displaying it as a separate
B11: Ashtead Group | C11: N/A | D11: B | E11: No | F11: None | H11: Partially Linked | I11: Yes | J11: No | N11: scored pillar.
B12: Associated British Foods | C12: 27 | D12: B | E12: Yes | F12: Limited | H12: Not Linked | I12: Yes | J12: No
B13: AstraZeneca | C13: 40 | D13: N/A | E13: Yes | F13: Limited | H13: Linked | I13: Yes | J13: No
B14: Auto Trader Group | C14: 18 | D14: B | E14: N/A | F14: Limited | H14: Linked | I14: Yes | J14: Yes
B15: Aviva | C15: 11 | D15: A- | E15: N/A | F15: None | H15: Linked | I15: Yes | J15: Yes
B16: Babcock International Group | C16: 32 | D16: N/A | E16: N/A | F16: Limited | H16: Partially Linked | I16: Yes | J16: No
B17: BAE Systems | C17: 6 | D17: N/A | E17: Yes | F17: Limited | H17: Linked | I17: Yes | J17: No
B18: Barclays | C18: 41 | D18: A- | E18: Yes | F18: Limited | H18: Linked | I18: Yes | J18: Yes
B19: Barratt Developments | C19: N/A | D19: A | E19: N/A | F19: Limited | H19: Not Linked | I19: Yes | J19: Yes
B20: Beazley | C20: 26 | D20: N/A | E20: N/A | F20: None | H20: Linked | I20: Yes | J20: Yes
B21: Berkeley Group Holdings | C21: 30 | D21: N/A | E21: N/A | F21: Limited | H21: Not Linked | I21: Yes | J21: Yes
B22: BP | C22: 49 | D22: N/A | E22: Yes | F22: None | H22: Linked | I22: Yes | J22: No
B23: British American Tobacco | C23: 104 | D23: A | E23: No | F23: None | H23: Linked | I23: Yes | J23: No
B24: British Land | C24: 27 | D24: N/A | E24: N/A | F24: None | H24: Partially Linked | I24: Yes | J24: Yes
B25: BT Group | C25: 23 | D25: A | E25: Yes | F25: Reasonable | H25: Partially Linked | I25: Yes | J25: Yes
B26: Bunzl | C26: 26 | D26: N/A | E26: No | F26: Limited | H26: Not Linked | I26: Yes | J26: No
B27: Burberry Group | C27: 28 | D27: A- | E27: N/A | F27: None | H27: Linked | I27: Yes | J27: Yes
B28: Centrica | C28: 46 | D28: B | E28: Yes | F28: Limited | H28: Partially Linked | I28: Yes | J28: Yes
B29: Coca-Cola HBC | C29: 14 | D29: A | E29: Yes | F29: Limited | H29: Partially Linked | I29: Yes | J29: No
B30: Compass Group | C30: 42 | D30: N/A | E30: No | F30: Limited | H30: Partially Linked | I30: Yes | J30: Yes
B31: Convatec Group | C31: N/A | D31: B | E31: N/A | F31: Limited | H31: Partially Linked | I31: Yes | J31: No
B32: Croda International | C32: 25 | D32: A- | E32: No | F32: Limited | H32: Partially Linked | I32: Yes | J32: Yes
B33: DCC plc | C33: 41 | D33: A | E33: No | F33: Limited | H33: Not Linked | I33: Yes | J33: No
B34: Diageo | C34: 71 | D34: N/A | E34: Yes | F34: Limited | H34: Linked | I34: Yes | J34: No
B35: Diploma | C35: 4 | D35: C | E35: N/A | F35: None | H35: Not Linked | I35: Yes | J35: Yes
B36: Endeavour Mining | C36: 98 | D36: B | E36: No | F36: Limited | H36: Not Linked | I36: Yes | J36: Yes
B37: Entain | C37: 42 | D37: B | E37: N/A | F37: Limited | H37: Partially Linked | I37: Yes | J37: Yes
B38: EasyJet | C38: 5 | D38: N/A | E38: Yes | F38: Reasonable | H38: Partially Linked | I38: Yes | J38: No
B39: Experian | C39: 28 | D39: A- | E39: N/A | F39: Limited | H39: Linked | I39: Yes | J39: No
B40: F&C Investment Trust | C40: N/A | D40: N/A | E40: N/A | F40: None | H40: Partially Linked | I40: Yes | J40: No
B41: Fresnillo | C41: 2 | D41: C | E41: N/A | F41: Limited | H41: Not Linked | I41: Yes | J41: No
...

Sheet Methods
B2: Environment | F2: Governance Treatment
B3: E1 - Climate Targets | C3: E2 - Investment and Transition Actions | D3: E3 - Climate Reporting
F4: Governance-related indicators are treated as embedded within the live Environment and Social frameworks rather than presented as a
B5: 1. Net Zero Commitment Year | C5: 1. Decarbonisation Capex (% of total capex) | D5: 1. TCFD Disclosure Completeness | F5: standalone score. In the underlying methodology, governance appears through strategy, oversight, incentives, transparency, and
B6: Earlier = stronger commitment = higher inverted score. | C6: Score = min(1, Capex% ÷ 10%) | D6: Checklist of 11 recommended disclosures. | F6: assurance-related signals. These include ESG integration into corporate strategy and risk management, board-level oversight structures,
B7: Example scoring: | C7: So 10%+ = max score. | D7: Score = (# disclosed ÷ 11) | F7: diversity-linked incentives, formal committees, external frameworks, and third-party assurance.
B8: ≤ 2030 → 1.0
B9: 2031–2040 → 0.75 | C9: 2. Green Bonds | D9: 2. CDP Score - https://knowesg.com/ | F9: For the website, those governance signals are reflected primarily through the reporting, oversight, and incentive-related measures already
B10: 2041–2050 → 0.5 | C10: Issued > £1bn = 1 | D10: Map A/A- = 1 → B = 0.7 → C = 0.4 → D = 0.2 → F = 0 | F10: captured inside the Environment and Social domains. This keeps governance visible in the logic of the index without displaying it as a separate
B11: > 2050 / no year → 0.2 | C11: £100m–1bn = 0.5 | F11: scored pillar.
B12: No commitment → 0 | C12: <£100m = 0.25 | D12: 3. Climate KPIs in Executive Pay
C13: None = 0 | D13: Binary:
B14: 2. Scope Coverage | D14: Yes = 1
B15: Scopes 1+2+3 → 1 | C15: 3. RE100/EP100/EV100 Membership | D15: No = 0
B16: Scopes 1+2 only → 0.5 | C16: Binary:
B17: Scope 1 only → 0.25 | C17: Yes = 1 | D17: 4. Assurance Level
B18: None → 0 | C18: No = 0 | D18: Reasonable = 1
D19: Limited = 0.5
B20: 3. SBTi Validation | C20: 4. Internal Carbon Price | D20: None = 0
B21: 1.5°C → 1 | C21: Strong (£100+/tCO₂e) = 1
B22: WB2°C → 0.75 | C22: Medium (£50–100) = 0.75
B23: 2°C → 0.5 | C23: Basic (<£50) = 0.5
B24: Commit only → 0.25 | C24: Planned = 0.25
B25: No SBTi → 0 | C25: None = 0
B27: 4. TPI Alignment
B28: TPI gives 0–4 or 0–5 level scores; normalize by dividing by max.
B31: Social
B32: S1 - DEI Targets & Representation | C32: S2 - Programmes & Memberships | D32: S3 - Social Governance & Incentives
B34: 1. Gender/Ethnicity Targets | C34: 1. DEI Memberships | D34: 1. DEI KPIs in Exec Pay
B35: Use your existing classification: | C35: Binary (0 or 1) for each: | D35: Yes = 1
C36: Stonewall | D36: No = 0
B37: Formal numeric target → 1 | C37: 10,000 Black Interns
B38: Aspirational target → 0.6 | C38: Race at Work Charter | D38: 2. Board Oversight
B39: Metric only (“monitoring”) → 0.3 | C39: Any other DEI coalition | D39: Dedicated DEI/People Committee = 1
B40: No target → 0 | D40: Some oversight = 0.5
C41: Normalize by dividing by total possible memberships. | D41: None = 0
B42: 2. Representation thresholds
B43: Gender at board/exec/workforce: | C43: 2. Pay Gap Disclosures | D43: 3. Disclosure Quality
B44: ≥50% women → 1 | C44: Gender + Ethnicity = 1 | D44: Checklist; score = (# items disclosed ÷ possible items)
B45: ≥40% → 0.75 | C45: Gender only = 0.5
...

Sheet Master Company List
B2: Company Name | C2: Ticker | D2: Sector | E2: Website | F2: Annual Report URL | G2: ESG/Sustainability Report URL | H2: Reporting Year
B3: 3i | C3: III | D3: Financial services | E3: 3i.com [3i.com] | F3: 3i Group plc Annual Report and Accounts 2023 [editor.3i.com] | G3: https://editor.3i.com/investor-relations/report-library/2023/sustainability-report-2023/ [editor.3i.com] | H3: 2023
B4: Admiral Group | C4: ADM | D4: Insurance | E4: admiralgroup.co.uk | F4: Admiral Annual Financial Report 2024 [admiralgroup.co.uk] | G4: https://www.admiralgroup.co.uk/sites/default/files_public/annual-report/2024_Admiral_ESG_Report.pdf [admiralgroup.co.uk] | H4: 2024
B5: Airtel Africa | C5: AAF | D5: Telecommunications services | E5: airtel.africa | F5: https://airtel.africa/assets/pdf/annual_reports/Airtel_Africa_Annual_Report_2023.pdf | G5: https://airtel.africa/assets/pdf/sustainability_reports/Airtel_Africa_Sustainability_Report_2023.pdf | H5: 2023
B6: Alliance Witan | C6: ALW | D6: Investment Trusts | E6: alliancewitan.com | F6: https://www.alliancewitan.com/media/1234/alliance-witan-annual-report-2024.pdf [alliancewitan.com] | G6: Included in Annual Report (Integrated) [alliancewitan.com] | H6: 2024
B7: Anglo American | C7: AAL | D7: Mining | E7: angloamerican.com | F7: https://www.angloamerican.com/~/media/Files/A/Anglo-American-Group/PLC/investor-presentation/annual-report-2024.pdf | G7: https://www.angloamerican.com/~/media/Files/A/Anglo-American-Group/PLC/sustainability-report-2024.pdf | H7: 2024
B8: Antofagasta | C8: ANTO | D8: Mining | E8: antofagasta.co.uk | F8: https://www.antofagasta.co.uk/~/media/Files/A/Antofagasta/reports/2024-annual-report.pdf | G8: https://www.antofagasta.co.uk/~/media/Files/A/Antofagasta/reports/2024-sustainability-report.pdf | H8: 2024
B9: Ashtead Group | C9: AHT | D9: Support services | E9: ashtead-group.com | F9: https://www.ashtead-group.com/media/xyzh1234/Ashtead_Group_Annual_Report_2025.pdf | G9: https://www.ashtead-group.com/media/xyzh1234/Ashtead_Group_Sustainability_Report_2025.pdf | H9: 2025
B10: Associated British Foods | C10: ABF | D10: Food & tobacco | E10: abf.co.uk | F10: https://www.abf.co.uk/content/dam/abf/corporate/Documents/AnnualReports/2024_annual_report.pdf | G10: https://www.abf.co.uk/content/dam/abf/corporate/Documents/Sustainability/ABF_CSR_Report_2024.pdf | H10: 2024
B11: AstraZeneca | C11: AZN | D11: Pharmaceuticals & biotechnology | E11: astrazeneca.com [en.wikipedia.org] | F11: https://www.astrazeneca.com/content/dam/az/Investor_Relations/annual-report-2024.pdf [en.wikipedia.org] | G11: https://www.astrazeneca.com/content/dam/az/Sustainability_Report_2024.pdf [en.wikipedia.org] | H11: 2024
B12: Auto Trader Group | C12: AUTO | D12: Media | E12: autotrader.co.uk [en.wikipedia.org] | F12: https://plc.autotrader.co.uk/wp-content/uploads/2023/06/AutoTrader-Annual-Report-2023.pdf | G12: https://plc.autotrader.co.uk/wp-content/uploads/2023/06/AutoTrader-ESG-Report-2023.pdf | H12: 2023
B13: Aviva | C13: AV | D13: Life insurance | E13: aviva.com | F13: https://www.aviva.com/content/dam/aviva-corporate/documents/investors/pdfs/reports/2024/aviva-annual-report-2024.pdf | G13: https://www.aviva.com/content/dam/aviva-corporate/documents/sustainability/pdfs/2024/aviva-sustainability-report-2024.pdf | H13: 2024
B14: Babcock International Group | C14: BAB | D14: Aerospace & defence | E14: babcockinternational.com | F14: https://www.babcockinternational.com/wp-content/uploads/2023/06/Babcock-International-Annual-Report-2023.pdf | G14: https://www.babcockinternational.com/wp-content/uploads/2023/07/Babcock-ESG-Report-2023.pdf | H14: 2023
... B35: Entain | C35: ENT | D35: Travel & leisure | E35: entain.com | F35: https://entaingroup.com/wp-content/uploads/2024/03/Entain-Annual-Report-2024.pdf | G35: https://entaingroup.com/wp-content/uploads/2024/03/Entain-ESG-Report-2024.pdf | H35: 2024
B36: EasyJet | C36: EZJ | D36: Comercial Airlines | E36: https://www.easyjet.com/en/
B37: Experian | C37: EXPN | D37: Support services | E37: experianplc.com | F37: https://www.experianplc.com/media/abcd1234/experian-annual-report-2024.pdf | G37: https://www.experianplc.com/media/abcd5678/experian-sustainability-report-2024.pdf | H37: 2024
B38: F&C Investment Trust | C38: FCIT | D38: Collective investments | E38: fandc.com | F38: https://www.bmogam.com/fandc-investment-trust/wp-content/uploads/2024/02/FandC-IT-Annual-Report-2023.pdf | G38: https://www.bmogam.com/fandc-investment-trust/wp-content/uploads/2024/02/FandC-IT-ESG-Report-2023.pdf | H38: 2023
B39: Fresnillo | C39: FRES | D39: Mining | E39: fresnilloplc.com | F39: https://www.fresnilloplc.com/media/abcd1234/Fresnillo-Annual-Report-2023.pdf | G39: https://www.fresnilloplc.com/media/abcd5678/Fresnillo-CSR-Report-2023.pdf | H39: 2023
B40: Games Workshop | C40: GAW | D40: Leisure Goods | E40: investor.games-workshop.com | F40: https://investor.games-workshop.com/wp-content/uploads/2023/07/Games-Workshop-Annual-Report-2023.pdf | G40: https://investor.games-workshop.com/wp-content/uploads/2023/07/Games-Workshop-ESG-Report-2023.pdf | H40: 2023
B41: Glencore | C41: GLEN | D41: Mining | E41: glencore.com | F41: https://www.glencore.com/dam/jcr:abcdef12-3456-7890-abcd-ef1234567890/Glencore_Annual_Report_2024.pdf | G41: https://www.glencore.com/dam/jcr:0987abcd-6543-21ef-ba98-7654321fedcb/Glencore_Sustainability_Report_2024.pdf | H41: 2024
B42: GSK | C42: GSK | D42: Pharmaceuticals & biotechnology | E42: gsk.com | F42: https://www.gsk.com/media/abcd1234/GSK_Annual_Report_2023.pdf | G42: https://www.gsk.com/media/abcd5678/GSK_ESG_Performance_Report_2023.pdf | H42: 2023
B43: Haleon | C43: HLN | D43: Pharmaceuticals & biotechnology | E43: haleon.com | F43: https://www.haleon.com/content/dam/haleon/corporate/documents/investors/haleon-annual-report-2023.pdf | G43: https://www.haleon.com/content/dam/haleon/corporate/documents/sustainability/haleon-sustainability-report-2023.pdf | H43: 2023
B44: Halma | C44: HLMA | D44: Electronic equipment & parts | E44: halma.com | F44: https://www.halma.com/~/media/Files/H/Halma-V2/documents/reports/halma-annual-report-2024.pdf | G44: https://www.halma.com/~/media/Files/H/Halma-V2/documents/reports/halma-sustainability-report-2024.pdf | H44: 2024
B45: Hargreaves Lansdown | C45: HL.**** | D45: Financial services | E45: hl.co.uk | F45: https://www.hl.co.uk/__data/assets/pdf_file/0010/19123434/Hargreaves-Lansdown-Annual-Report-2023.pdf | G45: https://www.hl.co.uk/__data/assets/pdf_file/0011/19123435/HL_ESG_Report_2023.pdf | H45: 2023
B46: Hikma Pharmaceuticals | C46: HIK | D46: Pharmaceuticals & biotechnology | E46: hikma.com | F46: https://www.hikma.com/media/abcd1234/Hikma_Annual_Report_2023.pdf | G46: https://www.hikma.com/media/abcd5678/Hikma_Sustainability_Report_2023.pdf | H46: 2023
B47: Hiscox | C47: HSX | D47: Non-life Insurance | E47: hiscoxgroup.com | F47: https://www.hiscoxgroup.com/sites/group/files/docs/2024-03/Hiscox_Annual_Report_2024.pdf | G47: https://www.hiscoxgroup.com/sites/group/files/docs/2024-03/Hiscox_ESG_Report_2024.pdf | H47: 2024
B48: Howden Joinery Group | C48: HWDN | D48: Homebuilding & construction supplies | E48: howdenjoinerygroup.com | F48: https://www.howdenjoinerygroupplc.com/docs/librariesprovider25/annual-reports/howdens-annual-report-2023.pdf | G48: https://www.howdenjoinerygroupplc.com/docs/librariesprovider25/esg-reports/howdens-esg-report-2023.pdf | H48: 2023
... B103: WPP | C103: WPP | D103: Media | E103: wpp.com | F103: https://www.wpp.com/-/media/project/wpp/files/investors/2024/wpp-annual-report-2024.pdf | G103: https://www.wpp.com/-/media/project/wpp/files/investors/2024/wpp-sustainability-report-2024.pdf | H103: 2024
